<mujoco model="base">
    <compiler angle="radian" autolimits="true" meshdir="./meshes/" inertiagrouprange="0 0" />
    <option impratio="20" cone="elliptic" density="1.2" viscosity="0.00002" timestep="0.001" />
    <option integrator="RK4" solver="PGS" iterations="5" gravity="0 0 -9.81" />
    <size memory="256M" />
  <asset>
  <texture type="skybox" builtin="gradient" rgb1=".3 .5 .7" rgb2="0 0 0" width="32" height="512" />
    <texture name="robot0_body" type="cube" builtin="flat" mark="cross" width="128" height="128" rgb1="0.8 0.6 0.4" rgb2="0.8 0.6 0.4" markrgb="1 1 1" random="0.01" />
    <material name="robot0_body" texture="robot0_body" texuniform="true" rgba="0.8 0.6 .4 1" />
    <texture name="robot0_grid" type="2d" builtin="checker" width="512" height="512" rgb1=".1 .2 .3" rgb2=".2 .3 .4" />
    <material name="robot0_grid" texture="robot0_grid" texrepeat="1 1" texuniform="true" reflectance="0.02" />
    <mesh name="robot0_base" file="/home/ming/Projects/draco3/TRILL-GR1/models/robots/gr1/./meshes/base.STL" />
    <mesh name="robot0_l_thigh_roll" file="/home/ming/Projects/draco3/TRILL-GR1/models/robots/gr1/./meshes/l_thigh_roll.STL" />
    <mesh name="robot0_l_thigh_yaw" file="/home/ming/Projects/draco3/TRILL-GR1/models/robots/gr1/./meshes/l_thigh_yaw.STL" />
    <mesh name="robot0_l_thigh_pitch" file="/home/ming/Projects/draco3/TRILL-GR1/models/robots/gr1/./meshes/l_thigh_pitch.STL" />
    <mesh name="robot0_l_shank_pitch" file="/home/ming/Projects/draco3/TRILL-GR1/models/robots/gr1/./meshes/l_shank_pitch.STL" />
    <mesh name="robot0_l_foot_pitch" file="/home/ming/Projects/draco3/TRILL-GR1/models/robots/gr1/./meshes/l_foot_pitch.STL" />
    <mesh name="robot0_l_foot_roll" file="/home/ming/Projects/draco3/TRILL-GR1/models/robots/gr1/./meshes/l_foot_roll.STL" />
    <mesh name="robot0_r_thigh_roll" file="/home/ming/Projects/draco3/TRILL-GR1/models/robots/gr1/./meshes/r_thigh_roll.STL" />
    <mesh name="robot0_r_thigh_yaw" file="/home/ming/Projects/draco3/TRILL-GR1/models/robots/gr1/./meshes/r_thigh_yaw.STL" />
    <mesh name="robot0_r_thigh_pitch" file="/home/ming/Projects/draco3/TRILL-GR1/models/robots/gr1/./meshes/r_thigh_pitch.STL" />
    <mesh name="robot0_r_shank_pitch" file="/home/ming/Projects/draco3/TRILL-GR1/models/robots/gr1/./meshes/r_shank_pitch.STL" />
    <mesh name="robot0_r_foot_pitch" file="/home/ming/Projects/draco3/TRILL-GR1/models/robots/gr1/./meshes/r_foot_pitch.STL" />
    <mesh name="robot0_r_foot_roll" file="/home/ming/Projects/draco3/TRILL-GR1/models/robots/gr1/./meshes/r_foot_roll.STL" />
    <mesh name="robot0_waist_yaw" file="/home/ming/Projects/draco3/TRILL-GR1/models/robots/gr1/./meshes/waist_yaw.STL" />
    <mesh name="robot0_waist_pitch" file="/home/ming/Projects/draco3/TRILL-GR1/models/robots/gr1/./meshes/waist_pitch.STL" />
    <mesh name="robot0_waist_roll" file="/home/ming/Projects/draco3/TRILL-GR1/models/robots/gr1/./meshes/waist_roll.STL" />
    <mesh name="robot0_head_yaw" file="/home/ming/Projects/draco3/TRILL-GR1/models/robots/gr1/./meshes/head_yaw.STL" />
    <mesh name="robot0_head_roll" file="/home/ming/Projects/draco3/TRILL-GR1/models/robots/gr1/./meshes/head_roll.STL" />
    <mesh name="robot0_head_pitch" file="/home/ming/Projects/draco3/TRILL-GR1/models/robots/gr1/./meshes/head_pitch.STL" />
    <mesh name="robot0_l_upper_arm_pitch" file="/home/ming/Projects/draco3/TRILL-GR1/models/robots/gr1/./meshes/l_upper_arm_pitch.STL" />
    <mesh name="robot0_l_upper_arm_roll" file="/home/ming/Projects/draco3/TRILL-GR1/models/robots/gr1/./meshes/l_upper_arm_roll.STL" />
    <mesh name="robot0_l_upper_arm_yaw" file="/home/ming/Projects/draco3/TRILL-GR1/models/robots/gr1/./meshes/l_upper_arm_yaw.STL" />
    <mesh name="robot0_l_lower_arm_pitch" file="/home/ming/Projects/draco3/TRILL-GR1/models/robots/gr1/./meshes/l_lower_arm_pitch.STL" />
    <mesh name="robot0_l_hand_yaw" file="/home/ming/Projects/draco3/TRILL-GR1/models/robots/gr1/./meshes/l_hand_yaw.STL" />
    <mesh name="robot0_l_hand_roll" file="/home/ming/Projects/draco3/TRILL-GR1/models/robots/gr1/./meshes/l_hand_roll.STL" />
    <mesh name="robot0_l_hand_pitch" file="/home/ming/Projects/draco3/TRILL-GR1/models/robots/gr1/./meshes/l_hand_pitch.STL" />
    <mesh name="robot0_r_upper_arm_pitch" file="/home/ming/Projects/draco3/TRILL-GR1/models/robots/gr1/./meshes/r_upper_arm_pitch.STL" />
    <mesh name="robot0_r_upper_arm_roll" file="/home/ming/Projects/draco3/TRILL-GR1/models/robots/gr1/./meshes/r_upper_arm_roll.STL" />
    <mesh name="robot0_r_upper_arm_yaw" file="/home/ming/Projects/draco3/TRILL-GR1/models/robots/gr1/./meshes/r_upper_arm_yaw.STL" />
    <mesh name="robot0_r_lower_arm_pitch" file="/home/ming/Projects/draco3/TRILL-GR1/models/robots/gr1/./meshes/r_lower_arm_pitch.STL" />
    <mesh name="robot0_r_hand_yaw" file="/home/ming/Projects/draco3/TRILL-GR1/models/robots/gr1/./meshes/r_hand_yaw.STL" />
    <mesh name="robot0_r_hand_roll" file="/home/ming/Projects/draco3/TRILL-GR1/models/robots/gr1/./meshes/r_hand_roll.STL" />
    <mesh name="robot0_r_hand_pitch" file="/home/ming/Projects/draco3/TRILL-GR1/models/robots/gr1/./meshes/r_hand_pitch.STL" />
  <material name="gripperright_metal" rgba="0.58 0.58 0.58 1" />
    <material name="gripperright_black" rgba="0.149 0.149 0.149 1" />        
    <material name="gripperright_gray" rgba="0.4627 0.4627 0.4627 1" />
    <material name="gripperright_white" rgba="0.9 0.9 0.9 1" />
    <material name="gripperright_silicone" rgba="0.1882 0.1882 0.1882 1" />

    <material name="gripperright_tendon_line" rgba="0.95 0.3 0.3 0" />
    <material name="gripperright_tendon_site" rgba="0.1882 0.1882 0.1882 0" />

    <mesh name="gripperright_mesh_finger1" file="/home/ming/Projects/draco3/TRILL-GR1/models/grippers/sake_ezgripper/meshes/ezgripper_gen2/SAKE_Finger_L1_Gen2.stl" />
    <mesh name="gripperright_mesh_finger2" file="/home/ming/Projects/draco3/TRILL-GR1/models/grippers/sake_ezgripper/meshes/ezgripper_gen2/SAKE_Finger_L2_Gen2.stl" />
    <mesh name="gripperright_mesh_palm_dual" file="/home/ming/Projects/draco3/TRILL-GR1/models/grippers/sake_ezgripper/meshes/ezgripper_gen2/SAKE_Palm_Dual_Gen2.stl" />
  <material name="gripperleft_metal" rgba="0.58 0.58 0.58 1" />
    <material name="gripperleft_black" rgba="0.149 0.149 0.149 1" />        
    <material name="gripperleft_gray" rgba="0.4627 0.4627 0.4627 1" />
    <material name="gripperleft_white" rgba="0.9 0.9 0.9 1" />
    <material name="gripperleft_silicone" rgba="0.1882 0.1882 0.1882 1" />

    <material name="gripperleft_tendon_line" rgba="0.95 0.3 0.3 0" />
    <material name="gripperleft_tendon_site" rgba="0.1882 0.1882 0.1882 0" />

    <mesh name="gripperleft_mesh_finger1" file="/home/ming/Projects/draco3/TRILL-GR1/models/grippers/sake_ezgripper/meshes/ezgripper_gen2/SAKE_Finger_L1_Gen2.stl" />
    <mesh name="gripperleft_mesh_finger2" file="/home/ming/Projects/draco3/TRILL-GR1/models/grippers/sake_ezgripper/meshes/ezgripper_gen2/SAKE_Finger_L2_Gen2.stl" />
    <mesh name="gripperleft_mesh_palm_dual" file="/home/ming/Projects/draco3/TRILL-GR1/models/grippers/sake_ezgripper/meshes/ezgripper_gen2/SAKE_Palm_Dual_Gen2.stl" />
  </asset>

  <visual>
    <map znear="0.001" />
  </visual>

  <actuator>
  <motor ctrllimited="true" ctrlrange="-20000 20000" joint="robot0_l_hip_roll" name="robot0_l_hip_roll" />
    <motor ctrllimited="true" ctrlrange="-20000 20000" joint="robot0_l_hip_yaw" name="robot0_l_hip_yaw" />
    <motor ctrllimited="true" ctrlrange="-20000 20000" joint="robot0_l_hip_pitch" name="robot0_l_hip_pitch" />
    <motor ctrllimited="true" ctrlrange="-20000 20000" joint="robot0_l_knee_pitch" name="robot0_l_knee_pitch" />
    <motor ctrllimited="true" ctrlrange="-20000 20000" joint="robot0_l_ankle_pitch" name="robot0_l_ankle_pitch" />
    <motor ctrllimited="true" ctrlrange="-20000 20000" joint="robot0_l_ankle_roll" name="robot0_l_ankle_roll" />

    <motor ctrllimited="true" ctrlrange="-20000 20000" joint="robot0_r_hip_roll" name="robot0_r_hip_roll" />
    <motor ctrllimited="true" ctrlrange="-20000 20000" joint="robot0_r_hip_yaw" name="robot0_r_hip_yaw" />
    <motor ctrllimited="true" ctrlrange="-20000 20000" joint="robot0_r_hip_pitch" name="robot0_r_hip_pitch" />
    <motor ctrllimited="true" ctrlrange="-20000 20000" joint="robot0_r_knee_pitch" name="robot0_r_knee_pitch" />
    <motor ctrllimited="true" ctrlrange="-20000 20000" joint="robot0_r_ankle_pitch" name="robot0_r_ankle_pitch" />
    <motor ctrllimited="true" ctrlrange="-20000 20000" joint="robot0_r_ankle_roll" name="robot0_r_ankle_roll" />

    
    <motor ctrllimited="true" ctrlrange="-20000 20000" joint="robot0_head_yaw" name="robot0_head_yaw" />
    <motor ctrllimited="true" ctrlrange="-20000 20000" joint="robot0_head_pitch" name="robot0_head_pitch" />
    <motor ctrllimited="true" ctrlrange="-20000 20000" joint="robot0_head_roll" name="robot0_head_roll" />

    <motor ctrllimited="true" ctrlrange="-20000 20000" joint="robot0_l_shoulder_pitch" name="robot0_l_shoulder_pitch" />
    <motor ctrllimited="true" ctrlrange="-20000 20000" joint="robot0_l_shoulder_roll" name="robot0_l_shoulder_roll" />
    <motor ctrllimited="true" ctrlrange="-20000 20000" joint="robot0_l_shoulder_yaw" name="robot0_l_shoulder_yaw" />
    <motor ctrllimited="true" ctrlrange="-20000 20000" joint="robot0_l_elbow_pitch" name="robot0_l_elbow_pitch" />
    <motor ctrllimited="true" ctrlrange="-20000 20000" joint="robot0_l_wrist_yaw" name="robot0_l_wrist_yaw" />
    <motor ctrllimited="true" ctrlrange="-20000 20000" joint="robot0_l_wrist_roll" name="robot0_l_wrist_roll" />
    <motor ctrllimited="true" ctrlrange="-20000 20000" joint="robot0_l_wrist_pitch" name="robot0_l_wrist_pitch" />

    <motor ctrllimited="true" ctrlrange="-20000 20000" joint="robot0_r_shoulder_pitch" name="robot0_r_shoulder_pitch" />
    <motor ctrllimited="true" ctrlrange="-20000 20000" joint="robot0_r_shoulder_roll" name="robot0_r_shoulder_roll" />
    <motor ctrllimited="true" ctrlrange="-20000 20000" joint="robot0_r_shoulder_yaw" name="robot0_r_shoulder_yaw" />
    <motor ctrllimited="true" ctrlrange="-20000 20000" joint="robot0_r_elbow_pitch" name="robot0_r_elbow_pitch" />
    <motor ctrllimited="true" ctrlrange="-20000 20000" joint="robot0_r_wrist_yaw" name="robot0_r_wrist_yaw" />
    <motor ctrllimited="true" ctrlrange="-20000 20000" joint="robot0_r_wrist_roll" name="robot0_r_wrist_roll" />
    <motor ctrllimited="true" ctrlrange="-20000 20000" joint="robot0_r_wrist_pitch" name="robot0_r_wrist_pitch" />
  <motor ctrllimited="true" ctrlrange="-20 20" joint="gripperright_joint_left_driver" gear="1" name="gripperright_torque_drive" />
  <motor ctrllimited="true" ctrlrange="-20 20" joint="gripperleft_joint_left_driver" gear="1" name="gripperleft_torque_drive" />
  </actuator>
  <worldbody>
    <camera mode="fixed" fovy="89" name="envview" pos="-2.0 0 0.75" quat="0.5 -0.5 -0.5 0.5" />
    <camera mode="fixed" fovy="60" name="backview" pos="-2.0 0 0.75" quat="0.5 -0.5 -0.5 0.5" />
    <camera mode="fixed" name="testview" pos="1.5 0.0 1.0" quat="0.5 -0.5 0.5 -0.5" />
    <camera mode="fixed" name="upview" pos="-1.0 0.0 2.0" quat="0.6532815 -0.2705981 -0.2705981 0.6532815 " />
    
    <camera mode="fixed" name="kitchenview" pos="1.2 0 1.0" quat="0.5 -0.5 0.5 -0.5" />
    <camera mode="fixed" name="objectview" pos="0.5 0.0 3" quat="0.7071 0 0 0.7071" />
    <camera mode="fixed" name="door_testview" pos="3.0 0.0 1.1" quat="0.5 -0.5 0.5 -0.5" />
    <camera mode="fixed" name="door_topview" pos="2.2 0.0 2" quat="0.7071 0 0 0.7071" />
    <camera mode="fixed" name="topview" pos="1.0 0.0 2.2" quat="0.7071 0 0 0.7071" />
    <geom size="3 3 0.1" pos="0 0 -0.1" quat="0 0 0 1" type="box" group="0" name="ground" rgba="0 0 0 0" margin="-0.005" conaffinity="15" condim="3" friction="1" />
  <body name="robot0_base">
      <inertial pos="-0.0508888 0.000109183 -0.0455794" quat="0.706855 0.707166 0.0123661 -0.0109307" mass="6.45117" diaginertia="0.0149302 0.0127972 0.00640923" />
      <geom type="mesh" contype="0" conaffinity="0" group="1" density="0" rgba="0.752941 0.752941 0.752941 1" mesh="robot0_base" name="robot0_g0_vis" />
      <geom size="0.04 0.04 0.04" pos="0 0 -0.06" type="box" rgba="0 0.5 0 1" name="robot0_g0_col" />
      <joint armature="0" limited="false" name="robot0_root" pos="0 0 0" type="free" frictionloss="0.1" damping="0.1" />
      <body name="robot0_torso_link">
        <body name="robot0_base_com" />
      </body>

      <body name="robot0_l_thigh_roll" pos="-0.047999 0.105 -0.057493">
        <inertial pos="0.04163 3.4568e-05 -0.0021382" quat="0.575529 0.581908 -0.40597 0.406619" mass="1.1437" diaginertia="0.00117548 0.00100413 0.000943892" />
        <joint name="robot0_l_hip_roll" pos="0 0 0" axis="1 0 1.221e-05" range="-0.09 0.79" frictionloss="0.1" damping="0.1" armature="2.5" />
        <geom type="mesh" contype="0" conaffinity="0" group="1" density="0" rgba="0.75294 0.75294 0.75294 1" mesh="robot0_l_thigh_roll" name="robot0_g1_vis" />
        <geom size="0.04 0.04 0.04" pos="-0.046 0 0" type="box" rgba="0 0.5 0 1" name="robot0_g1_col" />
        <body name="robot0_l_thigh_yaw" pos="0.048 0 -0.030499">
          <inertial pos="0.00018348 0.046462 -0.10389" quat="0.704251 -0.0226446 -0.0453749 0.708138" mass="3.9888" diaginertia="0.0163385 0.0100158 0.00924336" />
          <joint name="robot0_l_hip_yaw" pos="0 0 0" axis="1.2209e-05 6.8349e-05 1" range="-0.7 0.7" frictionloss="0.1" damping="0.1" armature="1.6666666666666667" />
          <geom type="mesh" contype="0" conaffinity="0" group="1" density="0" rgba="0.75294 0.75294 0.75294 1" mesh="robot0_l_thigh_yaw" name="robot0_g2_vis" />
          <geom size="0.04 0.04 0.04" pos="0 0 0.01" type="box" rgba="0 0.5 0 1" name="robot0_g2_col" />
          <body name="robot0_l_thigh_pitch" pos="0 0 -0.11">
            <inertial pos="0.0028493 -0.021688 -0.090886" quat="0.707411 -0.0125435 -0.0111264 0.706604" mass="6.369" diaginertia="0.0532352 0.0425096 0.0134363" />
            <joint name="robot0_l_hip_pitch" pos="0 0 0" axis="0 1 -6.8349e-05" range="-1.75 0.7" frictionloss="0.1" damping="0.1" armature="1.25" />
            <geom type="mesh" contype="0" conaffinity="0" group="1" density="0" rgba="0.75294 0.75294 0.75294 1" mesh="robot0_l_thigh_pitch" name="robot0_g3_vis" />
            <geom size="0.04 0.04 0.175" pos="0 0 -0.15" type="box" rgba="0 0.5 0 1" name="robot0_g3_col" />
            <body name="robot0_l_shank_pitch" pos="0 2.4606e-05 -0.36">
              <inertial pos="0.0024312 -2.9945e-05 -0.11554" quat="0.692137 0.00134576 0.00140217 0.721764" mass="2.1895" diaginertia="0.0162703 0.016117 0.00113627" />
              <joint name="robot0_l_knee_pitch" pos="0 0 0" axis="0 1 6.8349e-05" range="-0.09 1.92" frictionloss="0.1" damping="0.1" armature="1.0" />
              <geom type="mesh" contype="0" conaffinity="0" group="1" density="0" rgba="0.75294 0.75294 0.75294 1" mesh="robot0_l_shank_pitch" name="robot0_g4_vis" />
              <geom size="0.04 0.04 0.1" pos="0 0 -0.15" type="box" rgba="0 0.5 0 1" name="robot0_g4_col" />
              <body name="robot0_l_foot_pitch" pos="0 2.3239e-05 -0.34">
                <inertial pos="1.748e-11 4.3804e-11 0" quat="1 3.42295e-05 -6.07362e-06 -2.07897e-10" mass="0.080335" diaginertia="5.1022e-06 4.3976e-06 4.188e-06" />
                <joint name="robot0_l_ankle_pitch" pos="0 0 0" axis="0 1 6.8349e-05" range="-1.05 0.52" frictionloss="0.1" damping="0.1" armature="0.8333333333333334" />
                <geom type="mesh" contype="0" conaffinity="0" group="1" density="0" rgba="0.75294 0.75294 0.75294 1" mesh="robot0_l_foot_pitch" name="robot0_g5_vis" />
                <geom size="0.015 0.015 0.015" pos="0 0 0.01" type="box" rgba="0 0.5 0 1" name="robot0_g5_col" />
                <body name="robot0_l_foot_roll">
                  <inertial pos="0.039446 0.00035757 -0.038101" quat="-0.00087198 0.709539 -0.00177594 0.704664" mass="0.584" diaginertia="0.00271032 0.0024027 0.000369145" />
                  <joint name="robot0_l_ankle_roll" pos="0 0 0" axis="1 0 1.221e-05" range="-0.44 0.44" frictionloss="0.1" damping="0.1" armature="0.7142857142857143" />
                  <geom type="mesh" contype="0" conaffinity="0" group="1" density="0" rgba="0.75294 0.75294 0.75294 1" mesh="robot0_l_foot_roll" name="robot0_g6_vis" />
                  <geom name="robot0_l_foot_1" size="0.015 0.015 0.12" pos="0.05 0.02 -0.035" quat="0.707105 0 0.707108 0" type="box" rgba="0 0.5 0 1" />
                  <geom name="robot0_l_foot_2" size="0.015 0.015 0.12" pos="0.05 -0.02 -0.035" quat="0.707105 0 0.707108 0" type="box" rgba="0 0.5 0 1" />
                  <geom name="robot0_geom_left_A1_col" size="0.03 .08 0.12" pos="0.05 -0.018 -0.035" quat="0.707105 0 0.707108 0" type="box" rgba="0 0.5 0 1" />
                  <body name="robot0_left_foot" pos="0 0 -0.076" quat="1 0 0 0" />
                </body>
              </body>
            </body>
          </body>
        </body>
      </body>
      <body name="robot0_r_thigh_roll" pos="-0.047999 -0.105 -0.057508">
        <inertial pos="0.0416295 3.45678e-05 -0.00213824" quat="0.57555 0.581927 -0.405942 0.406589" mass="1.14367" diaginertia="0.00117548 0.00100417 0.000943891" />
        <joint name="robot0_r_hip_roll" pos="0 0 0" axis="1 0 1.221e-05" range="-0.79 0.09" frictionloss="0.1" damping="0.1" armature="0.625" />
        <geom type="mesh" contype="0" conaffinity="0" group="1" density="0" rgba="0.752941 0.752941 0.752941 1" mesh="robot0_r_thigh_roll" name="robot0_g7_vis" />
        <geom size="0.04 0.04 0.04" pos="-0.046 0 0" type="box" rgba="0 0.5 0 1" name="robot0_g6_col" />
        <body name="robot0_r_thigh_yaw" pos="0.048 0 -0.030499">
          <inertial pos="-0.00159762 -0.0464482 -0.103899" quat="0.709186 -0.0420808 -0.0194028 0.703497" mass="3.98882" diaginertia="0.0163388 0.0100142 0.00924469" />
          <joint name="robot0_r_hip_yaw" pos="0 0 0" axis="1.2209e-05 6.8349e-05 1" range="-0.7 0.7" frictionloss="0.1" damping="0.1" armature="0.5555555555555556" />
          <geom type="mesh" contype="0" conaffinity="0" group="1" density="0" rgba="0.752941 0.752941 0.752941 1" mesh="robot0_r_thigh_yaw" name="robot0_g8_vis" />
          <geom size="0.04 0.04 0.04" pos="0 0 0.01" type="box" rgba="0 0.5 0 1" name="robot0_g7_col" />
          <body name="robot0_r_thigh_pitch" pos="0 0 -0.11">
            <inertial pos="0.002842 0.0217009 -0.0919987" quat="0.706586 -0.0113774 -0.0126258 0.707423" mass="6.36895" diaginertia="0.0532349 0.0424818 0.0134641" />
            <joint name="robot0_r_hip_pitch" pos="0 0 0" axis="0 1 6.8349e-05" range="-1.75 0.7" frictionloss="0.1" damping="0.1" armature="0.5" />
            <geom type="mesh" contype="0" conaffinity="0" group="1" density="0" rgba="0.752941 0.752941 0.752941 1" mesh="robot0_r_thigh_pitch" name="robot0_g9_vis" />
            <geom size="0.04 0.04 0.175" pos="0 0 -0.15" type="box" rgba="0 0.5 0 1" name="robot0_g8_col" />
            <body name="robot0_r_shank_pitch" pos="0 2.4606e-05 -0.36">
              <inertial pos="0.00236658 4.56188e-05 -0.115532" quat="0.71872 0.00154106 0.00120241 0.695296" mass="2.18947" diaginertia="0.0162708 0.0161183 0.00113536" />
              <joint name="robot0_r_knee_pitch" pos="0 0 0" axis="0 1 -6.8349e-05" range="-0.09 1.92" frictionloss="0.1" damping="0.1" armature="0.45454545454545453" />
              <geom type="mesh" contype="0" conaffinity="0" group="1" density="0" rgba="0.752941 0.752941 0.752941 1" mesh="robot0_r_shank_pitch" name="robot0_g10_vis" />
              <geom size="0.04 0.04 0.1" pos="0 0 -0.15" type="box" rgba="0 0.5 0 1" name="robot0_g9_col" />
              <body name="robot0_r_foot_pitch" pos="0 2.3239e-05 -0.34">
                <inertial pos="1.75705e-11 4.40342e-11 0" quat="1 3.42336e-05 -6.07409e-06 -2.07938e-10" mass="0.0799219" diaginertia="5.11122e-06 4.40004e-06 4.17954e-06" />
                <joint name="robot0_r_ankle_pitch" pos="0 0 0" axis="0 1 6.8349e-05" range="-1.05 0.52" frictionloss="0.1" damping="0.1" armature="0.4166666666666667" />
                <geom type="mesh" contype="0" conaffinity="0" group="1" density="0" rgba="0.752941 0.752941 0.752941 1" mesh="robot0_r_foot_pitch" name="robot0_g11_vis" />
                <geom size="0.015 0.015 0.015" pos="0 0 0.01" type="box" rgba="0 0.5 0 1" name="robot0_g10_col" />
                <body name="robot0_r_foot_roll">
                  <inertial pos="0.043909 -0.00032475 -0.039419" quat="0.000727105 0.710094 0.00155959 0.704104" mass="0.58089" diaginertia="0.00280098 0.0024886 0.000368482" />
                  <joint name="robot0_r_ankle_roll" pos="0 0 0" axis="1 0 1.221e-05" range="-0.44 0.44" frictionloss="0.1" damping="0.1" armature="0.38461538461538464" />
                  <geom type="mesh" contype="0" conaffinity="0" group="1" density="0" rgba="0.75294 0.75294 0.75294 1" mesh="robot0_r_foot_roll" name="robot0_g12_vis" />
                  <geom name="robot0_r_foot_1" size="0.015 0.015 0.12" pos="0.05 0.02 -0.035" quat="0.707105 0 0.707108 0" type="box" rgba="0 0.5 0 1" />
                  <geom name="robot0_r_foot_2" size="0.015 0.015 0.12" pos="0.05 -0.02 -0.035" quat="0.707105 0 0.707108 0" type="box" rgba="0 0.5 0 1" />

                  <geom name="robot0_geom_right_A1_col" size="0.03 .08 0.12" pos="0.05 -0.018 -0.035" quat="0.707105 0 0.707108 0" type="box" rgba="0 0.5 0 1" />
                  <body name="robot0_right_foot" pos="0 0 -0.076" quat="1 0 0 0" />

                </body>
              </body>
            </body>
          </body>
        </body>
      </body>
      <body name="robot0_waist_yaw" pos="0 0 0.0065">
        <inertial pos="-0.010388 -0.00169636 0.0224709" quat="8.03475e-05 0.752953 -6.91813e-06 0.658075" mass="0.37886" diaginertia="0.000387148 0.000354992 0.000193448" />
        
        <geom type="mesh" contype="0" conaffinity="0" group="1" density="0" rgba="0.752941 0.752941 0.752941 1" mesh="robot0_waist_yaw" name="robot0_g13_vis" />
        <geom size="0.04 0.04 0.04" pos="0 0 -0.06" quat="0.707388 0.706825 0 0" type="box" rgba="0 0.5 0 1" name="robot0_g11_col" />
        <body name="robot0_waist_pitch" pos="0 0 0.055">
          <inertial pos="0.00229173 -0.00229364 0.0425378" quat="0.998452 -0.0194486 0.0162447 0.0495079" mass="4.40328" diaginertia="0.00487449 0.00487146 0.00355351" />
          
          <geom type="mesh" contype="0" conaffinity="0" group="1" density="0" rgba="0.752941 0.752941 0.752941 1" mesh="robot0_waist_pitch" name="robot0_g14_vis" />
          <geom size="0.04 0.04 0.06" type="box" rgba="0 0.5 0 1" name="robot0_g12_col" />
          <body name="robot0_waist_roll" pos="0 0 0.085">
            <inertial pos="-0.00982804 -1.2954e-05 0.160653" quat="0.999997 1.84368e-05 -0.00260593 -4.00255e-05" mass="7.34393" diaginertia="0.0305266 0.0217567 0.0136783" />
            
            <geom type="mesh" contype="0" conaffinity="0" group="1" density="0" rgba="0.752941 0.752941 0.752941 1" mesh="robot0_waist_roll" name="robot0_g15_vis" />
            <geom size="0.09 0.09 0.09" pos="0 0 0.15" type="box" rgba="0 0.5 0 1" name="robot0_g13_col" />
            <body name="robot0_head_yaw" pos="0 -2.3548e-05 0.34453">
              <inertial pos="0.000255273 -1.43143e-05 0.0571737" quat="0.698659 0.111628 0.112302 0.697713" mass="0.168425" diaginertia="0.00013241 0.000126266 6.86988e-05" />
              <joint name="robot0_head_yaw" pos="0 0 0" axis="-1.221e-05 -6.8349e-05 1" range="-2.71 2.71" frictionloss="0.1" damping="0.1" armature="0.35714285714285715" />
              <geom type="mesh" contype="0" conaffinity="0" group="1" density="0" rgba="0.752941 0.752941 0.752941 1" mesh="robot0_head_yaw" name="robot0_g16_vis" />
              <geom size="0.02 0.02 0.02" pos="0 0 -0.03" type="box" rgba="0 0.5 0 1" name="robot0_g14_col" />
              <body name="robot0_head_roll" pos="0 0 0.1225">
                <inertial pos="-0.000539717 0.00299723 -0.00194711" quat="0.498775 0.509039 0.50481 0.487104" mass="0.0189574" diaginertia="5.66154e-06 3.71917e-06 3.07146e-06" />
                <joint name="robot0_head_roll" pos="0 0 0" axis="1 0 1.221e-05" range="-0.35 0.35" frictionloss="0.1" damping="0.1" armature="0.3333333333333333" />
                <geom type="mesh" contype="0" conaffinity="0" group="1" density="0" rgba="0.752941 0.752941 0.752941 1" mesh="robot0_head_roll" name="robot0_g17_vis" />
                <geom size="0.02 0.02 0.02" pos="0 0 -0.1" type="box" rgba="0 0.5 0 1" name="robot0_g15_col" />
                <body name="robot0_head_pitch">
                  <inertial pos="0.0179937 0.000157203 -0.0107884" quat="-0.00317787 0.890883 0.0047882 0.454197" mass="0.315067" diaginertia="0.00129389 0.00105273 0.000852366" />
                  <joint name="robot0_head_pitch" pos="0 0 0" axis="0 1 6.8349e-05" range="-0.52 0.35" frictionloss="0.1" damping="0.1" armature="0.3125" />
                  <geom type="mesh" contype="0" conaffinity="0" group="1" density="0" rgba="0.752941 0.752941 0.752941 1" mesh="robot0_head_pitch" name="robot0_g18_vis" />
                  <geom size="0.05 0.05 0.05" type="box" rgba="0 0.5 0 1" name="robot0_g16_col" />
                </body>
              </body>
            </body>
            <body name="robot0_l_upper_arm_pitch" pos="0 0.12661 0.21727" quat="0.976289 0.216473 0 0">
              <inertial pos="0.00515733 0.0588337 0.000122944" quat="0.999793 0.0203364 -0.000117253 0.0011083" mass="0.777394" diaginertia="0.000546411 0.000340581 0.000319359" />
              <joint name="robot0_l_shoulder_pitch" pos="0 0 0" axis="0 1 0" range="-2.79 1.92" frictionloss="0.1" damping="0.1" armature="0.29411764705882354" />
              <geom type="mesh" contype="0" conaffinity="0" group="1" density="0" rgba="0.752941 0.752941 0.752941 1" mesh="robot0_l_upper_arm_pitch" name="robot0_g19_vis" />
              <geom size="0.02 0.02 0.02" type="box" rgba="0 0.5 0 1" name="robot0_g17_col" />
              <body name="robot0_l_upper_arm_roll" pos="0 0.067 0" quat="0.976289 -0.216473 0 0">
                <inertial pos="0.0260055 0.0238305 -0.0272078" quat="0.906707 0.298574 0.228734 -0.190834" mass="0.084111" diaginertia="9.66711e-05 8.99184e-05 2.54726e-05" />
                <joint name="robot0_l_shoulder_roll" pos="0 0 0" axis="1 0 -1.221e-05" range="-0.57 3.27" frictionloss="0.1" damping="0.1" armature="0.2777777777777778" />
                <geom type="mesh" contype="0" conaffinity="0" group="1" density="0" rgba="0.752941 0.752941 0.752941 1" mesh="robot0_l_upper_arm_roll" name="robot0_g20_vis" />
                <geom size="0.02 0.02 0.02" type="box" rgba="0 0.5 0 1" name="robot0_g18_col" />
                <body name="robot0_l_upper_arm_yaw" pos="0 0.040004 -0.057502">
                  <inertial pos="-4.12427e-05 0.00135031 -0.101007" quat="0.706543 0.0248514 -0.0268343 0.706724" mass="0.78993" diaginertia="0.000480863 0.000420363 0.000315608" />
                  <joint name="robot0_l_shoulder_yaw" pos="0 0 0" axis="1.221e-05 6.8349e-05 1" range="-2.97 2.97" frictionloss="0.1" damping="0.1" armature="0.2631578947368421" />
                  <geom type="mesh" contype="0" conaffinity="0" group="1" density="0" rgba="0.752941 0.752941 0.752941 1" mesh="robot0_l_upper_arm_yaw" name="robot0_g21_vis" />
                  <geom size="0.025 0.025 0.06" pos="0 0 -0.05" type="box" rgba="0 0.5 0 1" name="robot0_g19_col" />
                  <body name="robot0_l_lower_arm_pitch" pos="0 1.28869e-05 -0.188546">
                    <inertial pos="2.60519e-07 0.0196937 -0.0210902" quat="0.675254 -0.209845 0.209837 0.675252" mass="0.0553958" diaginertia="2.92256e-05 2.63267e-05 1.3293e-05" />
                    <joint name="robot0_l_elbow_pitch" pos="0 0 0" axis="0 1 6.83491e-05" range="-2.27 2.27" frictionloss="0.1" damping="0.1" armature="0.25" />
                    <geom type="mesh" contype="0" conaffinity="0" group="1" density="0" rgba="0.752941 0.752941 0.752941 1" mesh="robot0_l_lower_arm_pitch" name="robot0_g22_vis" />
                    <geom size="0.02 0.02 0.02" type="box" rgba="0 0.5 0 1" name="robot0_g20_col" />
                    <body name="robot0_l_hand_yaw" pos="0 0 -0.0405043">
                      <inertial pos="-4.20996e-05 0.000336116 -0.0559829" quat="0.999784 -0.0189715 -0.00676208 0.00509819" mass="0.606076" diaginertia="0.000747266 0.000709257 0.000280769" />
                      <joint name="robot0_l_wrist_yaw" pos="0 0 0" axis="1.221e-05 6.83491e-05 1" range="-2.97 2.97" frictionloss="0.1" damping="0.1" armature="0.23809523809523808" />
                      <geom type="mesh" contype="0" conaffinity="0" group="1" density="0" rgba="0.752941 0.752941 0.752941 1" mesh="robot0_l_hand_yaw" name="robot0_g23_vis" />
                      <geom size="0.03 0.03 0.085" pos="0 0 -0.1" type="box" rgba="0 0.5 0 1" name="robot0_g21_col" />
                      <body name="robot0_l_hand_roll" pos="0 1.3775e-05 -0.20155">
                        <inertial pos="-1.5483e-08 -0.00044846 -1.9394e-08" quat="0 0.7071 0 0.707114" mass="0.0054473" diaginertia="3.6036e-07 3.5527e-07 7.344e-08" />
                        <joint name="robot0_l_wrist_roll" pos="0 0 0" axis="1 0 -1.2211e-05" range="-0.61 0.61" frictionloss="0.1" damping="0.1" armature="0.22727272727272727" />
                        <geom type="mesh" contype="0" conaffinity="0" group="1" density="0" rgba="0.75294 0.75294 0.75294 1" mesh="robot0_l_hand_roll" name="robot0_g24_vis" />
                        <geom size="0.01 0.01 0.01" type="box" rgba="0 0.5 0 1" name="robot0_g22_col" />
                        <body name="robot0_l_hand_pitch">
                          <inertial pos="0.0071289 -0.0026192 -0.078567" quat="0.298548 0.646339 0.631172 0.307795" mass="0.5239" diaginertia="0.000345825 0.000211684 0.000195941" />
                          <joint name="robot0_l_wrist_pitch" pos="0 0 0" axis="0 1 6.8349e-05" range="-0.61 0.61" frictionloss="0.1" damping="0.1" armature="0.21739130434782608" />
                          
                          <geom size="0.02 0.02 0.02" pos="0 0 -0.07" type="box" rgba="0 0.5 0 1" name="robot0_g23_col" />
                          <body name="robot0_left_eef" pos="0 0 0" quat="0.707107 0 0 0.707107">
                            <body name="robot0_left_mount" quat="0 1 0 0"><body name="gripperleft_base">
      <geom name="gripperleft_geom_base_viz" type="mesh" mesh="gripperleft_mesh_palm_dual" quat="0 0.7071068 0 0.7071068" group="1" material="gripperleft_black" />
      <geom name="gripperleft_geom_base_col" type="box" pos="0 0 0.042" size="0.015 0.04 0.038" group="0" rgba="0 0 0.5 1" />
      <inertial mass="0.3" diaginertia="0.01 0.01 0.01" pos="0 0 0" />
      <site name="gripperleft_site_left_finger1" pos="0 0.03 0" size="0.01" material="gripperleft_tendon_site" />
      <site name="gripperleft_site_left_finger2" pos="0 0.03 0.062569" size="0.01" material="gripperleft_tendon_site" />
      <site name="gripperleft_site_right_finger1" pos="0 -0.03 0" size="0.01" material="gripperleft_tendon_site" />
      <site name="gripperleft_site_right_finger2" pos="0 -0.03 0.062569" size="0.01" material="gripperleft_tendon_site" />

    <body name="gripperleft_left_finger1" pos="0 0.03 0.072569" quat="-0.5 0.5 0.5 0.5">
      <joint name="gripperleft_joint_left_driver" axis="0 1 0" limited="true" range="-1.94 1.94" solimplimit="0.95 0.99 0.001" solreflimit="0.005 1" />
      <geom name="gripperleft_geom_left_finger1" type="mesh" mesh="gripperleft_mesh_finger1" group="1" material="gripperleft_white" />
      
      <geom name="gripperleft_geom_left_finger1_pad" type="box" pos="0.027 0 -0.012" size="0.008 0.014 0.001" group="1" material="gripperleft_black" />
      
      <geom name="gripperleft_geom_left_finger1_pad_col" type="box" pos="0.027 0 -0.012" size="0.008 0.014 0.001" group="0" rgba="0 0 0.5 1" />
      <inertial mass=".025" diaginertia="0.01 0.01 0.01" pos="0 0 0" />
      <site name="gripperleft_site_left_finger3" pos="0.042 0 0.01" size="0.01" material="gripperleft_tendon_site" />

    <body name="gripperleft_left_finger2" pos="0.052 0 0">
      <joint name="gripperleft_joint_left_coupler" axis="0 1 0" limited="true" range="0 1.94" solimplimit="0.95 0.99 0.001" solreflimit="0.005 1" stiffness="0.4" springref="0.0" frictionloss="0.1" />
      <geom name="gripperleft_geom_left_finger2" type="mesh" mesh="gripperleft_mesh_finger2" group="1" material="gripperleft_white" />
       
      <geom name="gripperleft_geom_left_finger2_pad" type="box" pos="0.040 0 0.002" quat="0.9838437 0 -0.1790296 0" size="0.02 0.014 0.001" group="1" material="gripperleft_black" />
      
      <geom name="gripperleft_geom_left_finger2_pad_col" type="box" pos="0.040 0 0.002" quat="0.9838437 0 -0.1790296 0" size="0.02 0.014 0.001" group="0" rgba="0 0 0.5 1" />
      <inertial mass=".025" diaginertia="0.01 0.01 0.01" pos="0 0 0" />
      <site name="gripperleft_site_left_finger4" pos="0.05 0 0.01" size="0.01" material="gripperleft_tendon_site" />

    </body>
    </body>

    <body name="gripperleft_right_finger1" pos="0 -0.03 0.072569" quat="0.5 0.5 -0.5 0.5">
      <joint name="gripperleft_joint_right_driver" axis="0 1 0" limited="true" range="-1.94 1.94" solimplimit="0.95 0.99 0.001" solreflimit="0.005 1" />
      <geom name="gripperleft_geom_right_finger1" type="mesh" mesh="gripperleft_mesh_finger1" group="1" material="gripperleft_white" />
      
      <geom name="gripperleft_geom_right_finger1_pad" type="box" pos="0.027 0 -0.012" size="0.008 0.014 0.001" group="1" material="gripperleft_black" />
      
      <geom name="gripperleft_geom_right_finger1_pad_col" type="box" pos="0.027 0 -0.012" size="0.008 0.014 0.001" group="0" rgba="0 0 0.5 1" />
      <inertial mass=".025" diaginertia="0.01 0.01 0.01" pos="0 0 0" />
      <site name="gripperleft_site_right_finger3" pos="0.042 0 0.01" size="0.01" material="gripperleft_tendon_site" />

    <body name="gripperleft_right_finger2" pos="0.052 0 0">
      <joint name="gripperleft_joint_right_coupler" axis="0 1 0" limited="true" range="0 1.94" solimplimit="0.95 0.99 0.001" solreflimit="0.005 1" stiffness="0.4" springref="0.0" frictionloss="0.1" />
      <geom name="gripperleft_geom_right_finger2" type="mesh" mesh="gripperleft_mesh_finger2" group="1" material="gripperleft_white" />
      
      <geom name="gripperleft_geom_right_finger2_pad" type="box" pos="0.040 0 0.002" quat="0.9838437 0 -0.1790296 0" size="0.02 0.014 0.001" group="1" material="gripperleft_black" />
      
      <geom name="gripperleft_geom_right_finger2_pad_col" type="box" pos="0.040 0 0.002" quat="0.9838437 0 -0.1790296 0" size="0.02 0.014 0.001" group="0" rgba="0 0 0.5 1" />
      <inertial mass=".025" diaginertia="0.01 0.01 0.01" pos="0 0 0" />
      <site name="gripperleft_site_right_finger4" pos="0.05 0 0.01" size="0.01" material="gripperleft_tendon_site" />

    </body>
    </body>

    <body name="gripperleft_eef" pos="0 0 0.13" quat="1 0 0 0">
      
        
  		
    </body>

    

  </body>

  </body>
                            <body name="robot0_left_hand" pos="0 0 0" />
                          </body>
                        </body>
                      </body>
                    </body>
                  </body>
                </body>
              </body>
            </body>
            <body name="robot0_r_upper_arm_pitch" pos="0 -0.12664 0.21725" quat="0.976303 -0.216409 0 0">
              <inertial pos="0.00515735 -0.0587916 0.000122944" quat="0.999675 -0.0254775 -0.000125407 -0.000494276" mass="0.777391" diaginertia="0.00054641 0.000340601 0.00031934" />
              <joint name="robot0_r_shoulder_pitch" pos="0 0 0" axis="0 1 0" range="-2.79 1.92" frictionloss="0.1" damping="0.1" armature="0.20833333333333334" />
              <geom type="mesh" contype="0" conaffinity="0" group="1" density="0" rgba="0.752941 0.752941 0.752941 1" mesh="robot0_r_upper_arm_pitch" name="robot0_g25_vis" />
              <geom size="0.02 0.02 0.02" type="box" rgba="0 0.5 0 1" name="robot0_g24_col" />
              <body name="robot0_r_upper_arm_roll" pos="0 -0.067 0" quat="0.976303 0.216409 0 0">
                <inertial pos="0.0260059 -0.0238264 -0.0272109" quat="0.906733 -0.298529 0.228698 0.190821" mass="0.0840989" diaginertia="9.66585e-05 8.99068e-05 2.54689e-05" />
                <joint name="robot0_r_shoulder_roll" pos="0 0 0" axis="1 0 -1.221e-05" range="-3.27 0.57" frictionloss="0.1" damping="0.1" armature="0.2" />
                <geom type="mesh" contype="0" conaffinity="0" group="1" density="0" rgba="0.752941 0.752941 0.752941 1" mesh="robot0_r_upper_arm_roll" name="robot0_g26_vis" />
                <geom size="0.02 0.02 0.02" type="box" rgba="0 0.5 0 1" name="robot0_g25_col" />
                <body name="robot0_r_upper_arm_yaw" pos="0 -0.039996 -0.057473">
                  <inertial pos="0.00017083 -0.00124148 -0.100981" quat="0.712176 -0.02561 0.0250075 0.701088" mass="0.78993" diaginertia="0.000481112 0.000420147 0.000315576" />
                  <joint name="robot0_r_shoulder_yaw" pos="0 0 0" axis="1.221e-05 6.8349e-05 1" range="-2.97 2.97" frictionloss="0.1" damping="0.1" armature="0.19230769230769232" />
                  <geom type="mesh" contype="0" conaffinity="0" group="1" density="0" rgba="0.752941 0.752941 0.752941 1" mesh="robot0_r_upper_arm_yaw" name="robot0_g27_vis" />
                  <geom size="0.025 0.025 0.06" pos="0 0 -0.05" type="box" rgba="0 0.5 0 1" name="robot0_g26_col" />
                  <body name="robot0_r_lower_arm_pitch" pos="0 1.28859e-05 -0.18853">
                    <inertial pos="2.54538e-07 -0.0196908 -0.0210929" quat="0.675237 0.209883 -0.209892 0.67524" mass="0.0553958" diaginertia="2.92256e-05 2.63267e-05 1.3293e-05" />
                    <joint name="robot0_r_elbow_pitch" pos="0 0 0" axis="0 1 -6.835e-05" range="-2.27 2.27" frictionloss="0.1" damping="0.1" armature="0.18518518518518517" />
                    <geom type="mesh" contype="0" conaffinity="0" group="1" density="0" rgba="0.752941 0.752941 0.752941 1" mesh="robot0_r_lower_arm_pitch" name="robot0_g28_vis" />
                    <geom size="0.02 0.02 0.02" type="box" rgba="0 0.5 0 1" name="robot0_g27_col" />
                    <body name="robot0_r_hand_yaw" pos="0 0 -0.0405">
                      <inertial pos="0.000158044 -0.000478822 -0.0559415" quat="0.999772 0.019131 0.00724385 -0.00608553" mass="0.606076" diaginertia="0.000748132 0.000708413 0.000280748" />
                      <joint name="robot0_r_wrist_yaw" pos="0 0 0" axis="1.221e-05 6.835e-05 1" range="-2.97 2.97" frictionloss="0.1" damping="0.1" armature="0.17857142857142858" />
                      <geom type="mesh" contype="0" conaffinity="0" group="1" density="0" rgba="0.752941 0.752941 0.752941 1" mesh="robot0_r_hand_yaw" name="robot0_g29_vis" />
                      <geom size="0.03 0.03 0.085" pos="0 0 -0.1" type="box" rgba="0 0.5 0 1" name="robot0_g28_col" />
                      <body name="robot0_r_hand_roll" pos="0 1.3775e-05 -0.20153">
                        <inertial pos="1.5545e-08 0.00044846 4.1938e-08" quat="0 0.707105 0 0.707108" mass="0.0054473" diaginertia="3.6036e-07 3.5527e-07 7.344e-08" />
                        <joint name="robot0_r_wrist_roll" pos="0 0 0" axis="1 0 1.221e-05" range="-0.61 0.61" frictionloss="0.1" damping="0.1" armature="0.1724137931034483" />
                        <geom type="mesh" contype="0" conaffinity="0" group="1" density="0" rgba="0.75294 0.75294 0.75294 1" mesh="robot0_r_hand_roll" name="robot0_g30_vis" />
                        <geom size="0.01 0.01 0.01" type="box" rgba="0 0.5 0 1" name="robot0_g29_col" />
                        <body name="robot0_r_hand_pitch">
                          <inertial pos="0.0060733 0.0018907 -0.084578" quat="0.647336 -0.27161 -0.257721 0.6639" mass="0.53221" diaginertia="0.000319947 0.000196296 0.000182477" />
                          <joint name="robot0_r_wrist_pitch" pos="0 0 0" axis="0 1 -6.835e-05" range="-0.61 0.61" frictionloss="0.1" damping="0.1" armature="0.16666666666666666" />
                          
                          <geom size="0.02 0.02 0.04" pos="0 0 -0.07" type="box" rgba="0 0.5 0 1" name="robot0_g30_col" />
                          <body name="robot0_right_eef" pos="0 0 0" quat="-0.707107 0 0 0.707107">
                            <body name="robot0_right_mount" quat="0 1 0 0"><body name="gripperright_base">
      <geom name="gripperright_geom_base_viz" type="mesh" mesh="gripperright_mesh_palm_dual" quat="0 0.7071068 0 0.7071068" group="1" material="gripperright_black" />
      <geom name="gripperright_geom_base_col" type="box" pos="0 0 0.042" size="0.015 0.04 0.038" group="0" rgba="0 0 0.5 1" />
      <inertial mass="0.3" diaginertia="0.01 0.01 0.01" pos="0 0 0" />
      <site name="gripperright_site_left_finger1" pos="0 0.03 0" size="0.01" material="gripperright_tendon_site" />
      <site name="gripperright_site_left_finger2" pos="0 0.03 0.062569" size="0.01" material="gripperright_tendon_site" />
      <site name="gripperright_site_right_finger1" pos="0 -0.03 0" size="0.01" material="gripperright_tendon_site" />
      <site name="gripperright_site_right_finger2" pos="0 -0.03 0.062569" size="0.01" material="gripperright_tendon_site" />

    <body name="gripperright_left_finger1" pos="0 0.03 0.072569" quat="-0.5 0.5 0.5 0.5">
      <joint name="gripperright_joint_left_driver" axis="0 1 0" limited="true" range="-1.94 1.94" solimplimit="0.95 0.99 0.001" solreflimit="0.005 1" />
      <geom name="gripperright_geom_left_finger1" type="mesh" mesh="gripperright_mesh_finger1" group="1" material="gripperright_white" />
      
      <geom name="gripperright_geom_left_finger1_pad" type="box" pos="0.027 0 -0.012" size="0.008 0.014 0.001" group="1" material="gripperright_black" />
      
      <geom name="gripperright_geom_left_finger1_pad_col" type="box" pos="0.027 0 -0.012" size="0.008 0.014 0.001" group="0" rgba="0 0 0.5 1" />
      <inertial mass=".025" diaginertia="0.01 0.01 0.01" pos="0 0 0" />
      <site name="gripperright_site_left_finger3" pos="0.042 0 0.01" size="0.01" material="gripperright_tendon_site" />

    <body name="gripperright_left_finger2" pos="0.052 0 0">
      <joint name="gripperright_joint_left_coupler" axis="0 1 0" limited="true" range="0 1.94" solimplimit="0.95 0.99 0.001" solreflimit="0.005 1" stiffness="0.4" springref="0.0" frictionloss="0.1" />
      <geom name="gripperright_geom_left_finger2" type="mesh" mesh="gripperright_mesh_finger2" group="1" material="gripperright_white" />
       
      <geom name="gripperright_geom_left_finger2_pad" type="box" pos="0.040 0 0.002" quat="0.9838437 0 -0.1790296 0" size="0.02 0.014 0.001" group="1" material="gripperright_black" />
      
      <geom name="gripperright_geom_left_finger2_pad_col" type="box" pos="0.040 0 0.002" quat="0.9838437 0 -0.1790296 0" size="0.02 0.014 0.001" group="0" rgba="0 0 0.5 1" />
      <inertial mass=".025" diaginertia="0.01 0.01 0.01" pos="0 0 0" />
      <site name="gripperright_site_left_finger4" pos="0.05 0 0.01" size="0.01" material="gripperright_tendon_site" />

    </body>
    </body>

    <body name="gripperright_right_finger1" pos="0 -0.03 0.072569" quat="0.5 0.5 -0.5 0.5">
      <joint name="gripperright_joint_right_driver" axis="0 1 0" limited="true" range="-1.94 1.94" solimplimit="0.95 0.99 0.001" solreflimit="0.005 1" />
      <geom name="gripperright_geom_right_finger1" type="mesh" mesh="gripperright_mesh_finger1" group="1" material="gripperright_white" />
      
      <geom name="gripperright_geom_right_finger1_pad" type="box" pos="0.027 0 -0.012" size="0.008 0.014 0.001" group="1" material="gripperright_black" />
      
      <geom name="gripperright_geom_right_finger1_pad_col" type="box" pos="0.027 0 -0.012" size="0.008 0.014 0.001" group="0" rgba="0 0 0.5 1" />
      <inertial mass=".025" diaginertia="0.01 0.01 0.01" pos="0 0 0" />
      <site name="gripperright_site_right_finger3" pos="0.042 0 0.01" size="0.01" material="gripperright_tendon_site" />

    <body name="gripperright_right_finger2" pos="0.052 0 0">
      <joint name="gripperright_joint_right_coupler" axis="0 1 0" limited="true" range="0 1.94" solimplimit="0.95 0.99 0.001" solreflimit="0.005 1" stiffness="0.4" springref="0.0" frictionloss="0.1" />
      <geom name="gripperright_geom_right_finger2" type="mesh" mesh="gripperright_mesh_finger2" group="1" material="gripperright_white" />
      
      <geom name="gripperright_geom_right_finger2_pad" type="box" pos="0.040 0 0.002" quat="0.9838437 0 -0.1790296 0" size="0.02 0.014 0.001" group="1" material="gripperright_black" />
      
      <geom name="gripperright_geom_right_finger2_pad_col" type="box" pos="0.040 0 0.002" quat="0.9838437 0 -0.1790296 0" size="0.02 0.014 0.001" group="0" rgba="0 0 0.5 1" />
      <inertial mass=".025" diaginertia="0.01 0.01 0.01" pos="0 0 0" />
      <site name="gripperright_site_right_finger4" pos="0.05 0 0.01" size="0.01" material="gripperright_tendon_site" />

    </body>
    </body>

    <body name="gripperright_eef" pos="0 0 0.13" quat="1 0 0 0">
      
        
  		
    </body>

    

  </body>

  </body>
                            <body name="robot0_right_hand" pos="0 0 0" />
                          </body>
                        </body>
                      </body>
                    </body>
                  </body>
                </body>
              </body>
            </body>
          </body>
        </body>
      </body>
    </body>
  </worldbody>

  <equality>
  <tendon tendon1="gripperright_tendon_left" tendon2="gripperright_tendon_right" polycoef="0 1 0 0 0" solimp="0.95 0.99 0.001" solref="0.005 1" />
    <joint joint1="gripperright_joint_right_driver" joint2="gripperright_joint_left_driver" polycoef="0 1 0 0 0" solimp="0.95 0.99 0.001" solref="0.005 1" />
  <tendon tendon1="gripperleft_tendon_left" tendon2="gripperleft_tendon_right" polycoef="0 1 0 0 0" solimp="0.95 0.99 0.001" solref="0.005 1" />
    <joint joint1="gripperleft_joint_right_driver" joint2="gripperleft_joint_left_driver" polycoef="0 1 0 0 0" solimp="0.95 0.99 0.001" solref="0.005 1" />
  </equality>
<sensor /><tendon><spatial width="0.002" material="gripperright_tendon_line" name="gripperright_tendon_left" limited="true" range="0 0.5" springlength="0" frictionloss="0.1" stiffness="0.4">
      <site site="gripperright_site_left_finger1" />
      <site site="gripperright_site_left_finger2" />
      <site site="gripperright_site_left_finger3" />
      <site site="gripperright_site_left_finger4" />
    </spatial>

    <spatial width="0.002" material="gripperright_tendon_line" name="gripperright_tendon_right" limited="true" range="0 0.5" springlength="0" frictionloss="0.1" stiffness="0.4">
      <site site="gripperright_site_right_finger1" />
      <site site="gripperright_site_right_finger2" />
      <site site="gripperright_site_right_finger3" />
      <site site="gripperright_site_right_finger4" />
    </spatial>

  <spatial width="0.002" material="gripperleft_tendon_line" name="gripperleft_tendon_left" limited="true" range="0 0.5" springlength="0" frictionloss="0.1" stiffness="0.4">
      <site site="gripperleft_site_left_finger1" />
      <site site="gripperleft_site_left_finger2" />
      <site site="gripperleft_site_left_finger3" />
      <site site="gripperleft_site_left_finger4" />
    </spatial>

    <spatial width="0.002" material="gripperleft_tendon_line" name="gripperleft_tendon_right" limited="true" range="0 0.5" springlength="0" frictionloss="0.1" stiffness="0.4">
      <site site="gripperleft_site_right_finger1" />
      <site site="gripperleft_site_right_finger2" />
      <site site="gripperleft_site_right_finger3" />
      <site site="gripperleft_site_right_finger4" />
    </spatial>

  </tendon><contact /></mujoco>